<?xml version="1.0"?>
<robot name="my_robot" xmlns:xacro="http://www.ros.org/wiki/xacro">

    <!-- ========== MATERIALS ========== -->
    <material name="blue">
        <color rgba="0 0 0.5 1" />
    </material>
    <material name="grey">
        <color rgba="0.5 0.5 0.5 1" />
    </material>

    <!-- ========== BASE LINKS ========== -->
    <link name="base_footprint" />

    <link name="base_link">
        <visual>
            <geometry>
                <box size="0.6 0.4 0.2" />
            </geometry>
            <origin xyz="0 0 0.1" rpy="0 0 0" />
            <material name="blue" />
        </visual>
    </link>

    <!-- ========== WHEEL LINKS ========== -->
    <link name="front_left_wheel_link">
        <visual>
            <geometry>
                <cylinder radius="0.1" length="0.05" />
            </geometry>
            <origin xyz="0 0 0" rpy="1.5708 0 0" />
            <material name="grey" />
        </visual>
    </link>
    <link name="front_right_wheel_link">
        <visual>
            <geometry>
                <cylinder radius="0.1" length="0.05" />
            </geometry>
            <origin xyz="0 0 0" rpy="1.5708 0 0" />
            <material name="grey" />
        </visual>
    </link>
    <link name="back_left_wheel_link">
        <visual>
            <geometry>
                <cylinder radius="0.1" length="0.05" />
            </geometry>
            <origin xyz="0 0 0" rpy="1.5708 0 0" />
            <material name="grey" />
        </visual>
    </link>
    <link name="back_right_wheel_link">
        <visual>
            <geometry>
                <cylinder radius="0.1" length="0.05" />
            </geometry>
            <origin xyz="0 0 0" rpy="1.5708 0 0" />
            <material name="grey" />
        </visual>
    </link>

    <!-- ========== JOINTS ========== -->
    <joint name="base_joint" type="fixed">
        <parent link="base_footprint" />
        <child link="base_link" />
        <origin xyz="0 0 0.1" rpy="0 0 0"/>
    </joint>

    <joint name="front_left_wheel_joint" type="continuous">
        <parent link="base_link" />
        <child link="front_left_wheel_link" />
        <origin xyz="0.15 0.225 0" rpy="0 0 0" />
        <axis xyz="0 1 0" />
    </joint>
    <joint name="front_right_wheel_joint" type="continuous">
        <parent link="base_link" />
        <child link="front_right_wheel_link" />
        <origin xyz="0.15 -0.225 0" rpy="0 0 0" />
        <axis xyz="0 1 0" />
    </joint>
    <joint name="back_left_wheel_joint" type="continuous">
        <parent link="base_link" />
        <child link="back_left_wheel_link" />
        <origin xyz="-0.15 0.225 0" rpy="0 0 0" />
        <axis xyz="0 1 0" />
    </joint>
    <joint name="back_right_wheel_joint" type="continuous">
        <parent link="base_link" />
        <child link="back_right_wheel_link" />
        <origin xyz="-0.15 -0.225 0" rpy="0 0 0" />
        <axis xyz="0 1 0" />
    </joint>
    <!-- For 6 wheels, add middle_left_wheel_joint and middle_right_wheel_joint with appropriate origins -->


    <!-- ========== ROS2 CONTROL ========== -->
    <ros2_control name="MobileBaseHardwareInterface" type="system">
        <hardware>
            <plugin>mock_components/GenericSystem</plugin>
            <param name="calculate_dynamics">true</param>
        </hardware>
        <joint name="front_left_wheel_joint">
            <command_interface name="velocity" />
            <state_interface name="position" />
            <state_interface name="velocity" />
        </joint>
        <joint name="front_right_wheel_joint">
            <command_interface name="velocity" />
            <state_interface name="position" />
            <state_interface name="velocity" />
        </joint>
        <joint name="back_left_wheel_joint">
            <command_interface name="velocity" />
            <state_interface name="position" />
            <state_interface name="velocity" />
        </joint>
        <joint name="back_right_wheel_joint">
            <command_interface name="velocity" />
            <state_interface name="position" />
            <state_interface name="velocity" />
        </joint>
                <!-- For 6 wheels:
        <joint name="middle_left_wheel_joint">
            <command_interface name="velocity" />
            <state_interface name="position" />
            <state_interface name="velocity" />
        </joint>
        <joint name="middle_right_wheel_joint">
            <command_interface name="velocity" />
            <state_interface name="position" />
            <state_interface name="velocity" />
        </joint>
        -->

    </ros2_control>

</robot>